<robot name="arac_Montaj1_urdf">
  <!-- Root Link -->
  <link name="base_footprint"/>

  <!-- Joint connecting base_footprint to base_link -->
  <joint name="base_footprint_to_base_link" type="fixed">
    <parent link="base_footprint"/>
    <child link="base_link"/>
  </joint>

  <!-- Define base_link -->
  <link name="base_link">
    <visual>
      <geometry>
        <box size="0.5 0.3 0.1"/>
      </geometry>
      <origin xyz="0 0 0.05" rpy="0 0 0"/>
    </visual>
  </link>

  <!-- Front left wheel (sol_on) -->
  <link name="sol_on">
    <visual>
      <geometry>
        <cylinder radius="0.05" length="0.02"/>
      </geometry>
      <origin xyz="0.2 0.1 0" rpy="0 0 0"/>
    </visual>
  </link>

  <!-- Joint connecting base_link to sol_on -->
  <joint name="base_to_sol_on" type="continuous">
    <parent link="base_link"/>
    <child link="sol_on"/>
    <origin xyz="0.2 0.1 0" rpy="0 0 0"/>
    <axis xyz="0 1 0"/>
  </joint>

  <!-- Front right wheel -->
  <link name="sag_on">
    <visual>
      <geometry>
        <cylinder radius="0.05" length="0.02"/>
      </geometry>
      <origin xyz="0.2 -0.1 0" rpy="0 0 0"/>
    </visual>
  </link>

  <joint name="base_to_sag_on" type="continuous">
    <parent link="base_link"/>
    <child link="sag_on"/>
    <origin xyz="0.2 -0.1 0" rpy="0 0 0"/>
    <axis xyz="0 1 0"/>
  </joint>

  <!-- Rear left wheel -->
  <link name="sol_arka">
    <visual>
      <geometry>
        <cylinder radius="0.05" length="0.02"/>
      </geometry>
      <origin xyz="-0.2 0.1 0" rpy="0 0 0"/>
    </visual>
  </link>

  <joint name="base_to_sol_arka" type="continuous">
    <parent link="base_link"/>
    <child link="sol_arka"/>
    <origin xyz="-0.2 0.1 0" rpy="0 0 0"/>
    <axis xyz="0 1 0"/>
  </joint>

  <!-- Rear right wheel -->
  <link name="sag_arka">
    <visual>
      <geometry>
        <cylinder radius="0.05" length="0.02"/>
      </geometry>
      <origin xyz="-0.2 -0.1 0" rpy="0 0 0"/>
    </visual>
  </link>

  <joint name="base_to_sag_arka" type="continuous">
    <parent link="base_link"/>
    <child link="sag_arka"/>
    <origin xyz="-0.2 -0.1 0" rpy="0 0 0"/>
    <axis xyz="0 1 0"/>
  </joint>

  <!-- Laser Frame -->
  <link name="laser_frame">
    <visual>
      <geometry>
        <cylinder radius="0.02" length="0.05"/>
      </geometry>
      <origin xyz="0 0 0.2" rpy="0 0 0"/>
    </visual>
  </link>

  <!-- Joint connecting base_link to laser_frame -->
  <joint name="base_to_laser" type="fixed">
    <parent link="base_link"/>
    <child link="laser_frame"/>
    <origin xyz="0 0 0.2" rpy="0 0 0"/>
  </joint>
</robot>
